2020-12-26 09:03:01,994 - WARNING | webdriver.py/_do_retry/67 | Cannot locate xpath retry #1
2020-12-26 09:04:41,661 - WARNING | webdriver.py/_do_retry/67 | Cannot locate xpath retry #1
2020-12-26 09:06:27,528 - WARNING | webdriver.py/_do_retry/67 | Cannot locate xpath retry #1
2020-12-26 09:08:11,889 - WARNING | webdriver.py/_do_retry/67 | Cannot locate xpath retry #1
2020-12-26 09:09:56,557 - WARNING | webdriver.py/_do_retry/67 | Cannot locate xpath retry #1
2020-12-26 09:11:08,657 - WARNING | webdriver.py/_do_retry/67 | Cannot locate xpath retry #1
2020-12-26 09:39:24,550 - ERROR | webdriver.py/_do_retry/70 | Exception found when retrying
Traceback (most recent call last):
  File "C:\Users\khova\AppData\Local\Programs\Python\Python38-32\lib\asyncio\runners.py", line 43, in run
    return loop.run_until_complete(main)
  File "C:\Users\khova\AppData\Local\Programs\Python\Python38-32\lib\asyncio\base_events.py", line 603, in run_until_complete
    self.run_forever()
  File "C:\Users\khova\AppData\Local\Programs\Python\Python38-32\lib\asyncio\windows_events.py", line 316, in run_forever
    super().run_forever()
  File "C:\Users\khova\AppData\Local\Programs\Python\Python38-32\lib\asyncio\base_events.py", line 570, in run_forever
    self._run_once()
  File "C:\Users\khova\AppData\Local\Programs\Python\Python38-32\lib\asyncio\base_events.py", line 1823, in _run_once
    event_list = self._selector.select(timeout)
  File "C:\Users\khova\AppData\Local\Programs\Python\Python38-32\lib\asyncio\windows_events.py", line 430, in select
    self._poll(timeout)
  File "C:\Users\khova\AppData\Local\Programs\Python\Python38-32\lib\asyncio\windows_events.py", line 779, in _poll
    status = _overlapped.GetQueuedCompletionStatus(self._iocp, ms)
  File "C:\Users\khova\AppData\Local\Programs\Python\Python38-32\lib\site-packages\pyppeteer\launcher.py", line 151, in _close_process
    self._loop.run_until_complete(self.killChrome())
  File "C:\Users\khova\AppData\Local\Programs\Python\Python38-32\lib\asyncio\base_events.py", line 592, in run_until_complete
    self._check_running()
  File "C:\Users\khova\AppData\Local\Programs\Python\Python38-32\lib\asyncio\base_events.py", line 552, in _check_running
    raise RuntimeError('This event loop is already running')
RuntimeError: This event loop is already running

During handling of the above exception, another exception occurred:

Traceback (most recent call last):
  File "..\webdriver.py", line 63, in _do_retry
    await operation()
  File "C:\Users\khova\AppData\Local\Programs\Python\Python38-32\lib\site-packages\pyppeteer\element_handle.py", line 177, in click
    await self._scrollIntoViewIfNeeded()
  File "C:\Users\khova\AppData\Local\Programs\Python\Python38-32\lib\site-packages\pyppeteer\element_handle.py", line 68, in _scrollIntoViewIfNeeded
    error = await self.executionContext.evaluate('''
  File "C:\Users\khova\AppData\Local\Programs\Python\Python38-32\lib\site-packages\pyppeteer\execution_context.py", line 53, in evaluate
    handle = await self.evaluateHandle(
  File "C:\Users\khova\AppData\Local\Programs\Python\Python38-32\lib\site-packages\pyppeteer\execution_context.py", line 99, in evaluateHandle
    _obj = await self._client.send('Runtime.callFunctionOn', {
asyncio.exceptions.CancelledError
2021-02-26 17:15:57,000 - WARNING | extractor.py/_scrape/120 | Error occured
Traceback (most recent call last):
  File "C:\Users\khova\AppData\Local\Programs\Python\Python38-32\lib\asyncio\runners.py", line 43, in run
    return loop.run_until_complete(main)
  File "C:\Users\khova\AppData\Local\Programs\Python\Python38-32\lib\asyncio\base_events.py", line 603, in run_until_complete
    self.run_forever()
  File "C:\Users\khova\AppData\Local\Programs\Python\Python38-32\lib\asyncio\windows_events.py", line 316, in run_forever
    super().run_forever()
  File "C:\Users\khova\AppData\Local\Programs\Python\Python38-32\lib\asyncio\base_events.py", line 570, in run_forever
    self._run_once()
  File "C:\Users\khova\AppData\Local\Programs\Python\Python38-32\lib\asyncio\base_events.py", line 1823, in _run_once
    event_list = self._selector.select(timeout)
  File "C:\Users\khova\AppData\Local\Programs\Python\Python38-32\lib\asyncio\windows_events.py", line 430, in select
    self._poll(timeout)
  File "C:\Users\khova\AppData\Local\Programs\Python\Python38-32\lib\asyncio\windows_events.py", line 779, in _poll
    status = _overlapped.GetQueuedCompletionStatus(self._iocp, ms)
  File "C:\Users\khova\AppData\Local\Programs\Python\Python38-32\lib\site-packages\pyppeteer\launcher.py", line 151, in _close_process
    self._loop.run_until_complete(self.killChrome())
  File "C:\Users\khova\AppData\Local\Programs\Python\Python38-32\lib\asyncio\base_events.py", line 592, in run_until_complete
    self._check_running()
  File "C:\Users\khova\AppData\Local\Programs\Python\Python38-32\lib\asyncio\base_events.py", line 552, in _check_running
    raise RuntimeError('This event loop is already running')
RuntimeError: This event loop is already running

During handling of the above exception, another exception occurred:

Traceback (most recent call last):
  File "extractor.py", line 114, in _scrape
    data = extract(await self._page.content())
  File "C:\Users\khova\AppData\Local\Programs\Python\Python38-32\lib\site-packages\pyppeteer\page.py", line 803, in content
    return await frame.content()
  File "C:\Users\khova\AppData\Local\Programs\Python\Python38-32\lib\site-packages\pyppeteer\frame_manager.py", line 384, in content
    return await self.evaluate('''
  File "C:\Users\khova\AppData\Local\Programs\Python\Python38-32\lib\site-packages\pyppeteer\frame_manager.py", line 308, in evaluate
    return await context.evaluate(
  File "C:\Users\khova\AppData\Local\Programs\Python\Python38-32\lib\site-packages\pyppeteer\execution_context.py", line 53, in evaluate
    handle = await self.evaluateHandle(
  File "C:\Users\khova\AppData\Local\Programs\Python\Python38-32\lib\site-packages\pyppeteer\execution_context.py", line 99, in evaluateHandle
    _obj = await self._client.send('Runtime.callFunctionOn', {
asyncio.exceptions.CancelledError
2021-02-26 17:18:00,115 - WARNING | webdriver.py/_do_retry/67 | Cannot locate xpath retry #1
2021-02-26 17:19:42,183 - WARNING | webdriver.py/_do_retry/67 | Cannot locate xpath retry #1
2021-02-26 17:21:25,899 - WARNING | webdriver.py/_do_retry/67 | Cannot locate xpath retry #1
2021-02-26 17:23:08,410 - WARNING | webdriver.py/_do_retry/67 | Cannot locate xpath retry #1
2021-02-26 17:24:53,350 - WARNING | webdriver.py/_do_retry/67 | Cannot locate xpath retry #1
2021-02-26 17:26:40,303 - WARNING | webdriver.py/_do_retry/67 | Cannot locate xpath retry #1
2021-02-26 17:28:27,005 - WARNING | webdriver.py/_do_retry/67 | Cannot locate xpath retry #1
2021-02-26 17:30:13,206 - WARNING | webdriver.py/_do_retry/67 | Cannot locate xpath retry #1
2021-02-26 17:31:58,209 - WARNING | webdriver.py/_do_retry/67 | Cannot locate xpath retry #1
2021-02-26 17:33:46,760 - WARNING | webdriver.py/_do_retry/67 | Cannot locate xpath retry #1
2021-02-26 17:35:35,841 - WARNING | webdriver.py/_do_retry/67 | Cannot locate xpath retry #1
2021-02-26 17:35:35,845 - ERROR | webdriver.py/_do_retry/70 | Exception found when retrying
Traceback (most recent call last):
  File "..\webdriver.py", line 65, in _do_retry
    await self._page.waitForXPath(xpath, {'visible': True})
  File "C:\Users\khova\AppData\Local\Programs\Python\Python38-32\lib\site-packages\pyppeteer\frame_manager.py", line 855, in __await__
    raise result
pyppeteer.errors.TimeoutError: Waiting for XPath "//*[@class="section-hero-header-title-title GLOBAL__gm2-headline-5"]" failed: timeout 30000ms exceeds.

During handling of the above exception, another exception occurred:

Traceback (most recent call last):
  File "..\webdriver.py", line 63, in _do_retry
    await operation()
  File "C:\Users\khova\AppData\Local\Programs\Python\Python38-32\lib\site-packages\pyppeteer\element_handle.py", line 177, in click
    await self._scrollIntoViewIfNeeded()
  File "C:\Users\khova\AppData\Local\Programs\Python\Python38-32\lib\site-packages\pyppeteer\element_handle.py", line 99, in _scrollIntoViewIfNeeded
    raise ElementHandleError(error)
pyppeteer.errors.ElementHandleError: Node is detached from document
2021-02-26 17:35:36,220 - WARNING | extractor.py/_scrape/120 | Error occured
Traceback (most recent call last):
  File "extractor.py", line 117, in _scrape
    back = (await self._page.xpath(back_xpath))[0]
IndexError: list index out of range
2021-02-26 17:36:45,623 - WARNING | extractor.py/_scrape/120 | Error occured
Traceback (most recent call last):
  File "extractor.py", line 111, in _scrape
    place = (await self._page.xpath(result_xpath))[i]
IndexError: list index out of range
2021-02-26 17:36:45,632 - WARNING | extractor.py/_scrape/120 | Error occured
Traceback (most recent call last):
  File "extractor.py", line 111, in _scrape
    place = (await self._page.xpath(result_xpath))[i]
IndexError: list index out of range
2021-02-26 17:37:17,806 - WARNING | webdriver.py/_do_retry/67 | Cannot locate xpath retry #1
2021-02-26 17:38:59,952 - WARNING | webdriver.py/_do_retry/67 | Cannot locate xpath retry #1
2021-02-26 17:39:16,978 - WARNING | extractor.py/_scrape/120 | Error occured
Traceback (most recent call last):
  File "extractor.py", line 111, in _scrape
    place = (await self._page.xpath(result_xpath))[i]
IndexError: list index out of range
2021-02-26 17:39:16,983 - WARNING | extractor.py/_scrape/120 | Error occured
Traceback (most recent call last):
  File "extractor.py", line 111, in _scrape
    place = (await self._page.xpath(result_xpath))[i]
IndexError: list index out of range
2021-02-26 17:39:16,989 - WARNING | extractor.py/_scrape/120 | Error occured
Traceback (most recent call last):
  File "extractor.py", line 111, in _scrape
    place = (await self._page.xpath(result_xpath))[i]
IndexError: list index out of range
2021-02-26 17:39:16,995 - WARNING | extractor.py/_scrape/120 | Error occured
Traceback (most recent call last):
  File "extractor.py", line 111, in _scrape
    place = (await self._page.xpath(result_xpath))[i]
IndexError: list index out of range
2021-02-26 17:39:17,000 - WARNING | extractor.py/_scrape/120 | Error occured
Traceback (most recent call last):
  File "extractor.py", line 111, in _scrape
    place = (await self._page.xpath(result_xpath))[i]
IndexError: list index out of range
2021-02-26 17:39:17,007 - WARNING | extractor.py/_scrape/120 | Error occured
Traceback (most recent call last):
  File "extractor.py", line 111, in _scrape
    place = (await self._page.xpath(result_xpath))[i]
IndexError: list index out of range
2021-02-26 17:39:17,014 - WARNING | extractor.py/_scrape/120 | Error occured
Traceback (most recent call last):
  File "extractor.py", line 111, in _scrape
    place = (await self._page.xpath(result_xpath))[i]
IndexError: list index out of range
2021-02-26 17:39:17,020 - WARNING | extractor.py/_scrape/120 | Error occured
Traceback (most recent call last):
  File "extractor.py", line 111, in _scrape
    place = (await self._page.xpath(result_xpath))[i]
IndexError: list index out of range
2021-02-26 17:39:17,025 - WARNING | extractor.py/_scrape/120 | Error occured
Traceback (most recent call last):
  File "extractor.py", line 111, in _scrape
    place = (await self._page.xpath(result_xpath))[i]
IndexError: list index out of range
2021-02-26 17:39:17,031 - WARNING | extractor.py/_scrape/120 | Error occured
Traceback (most recent call last):
  File "extractor.py", line 111, in _scrape
    place = (await self._page.xpath(result_xpath))[i]
IndexError: list index out of range
2021-02-26 17:39:17,036 - WARNING | extractor.py/_scrape/120 | Error occured
Traceback (most recent call last):
  File "extractor.py", line 111, in _scrape
    place = (await self._page.xpath(result_xpath))[i]
IndexError: list index out of range
2021-02-26 17:39:17,041 - WARNING | extractor.py/_scrape/120 | Error occured
Traceback (most recent call last):
  File "extractor.py", line 111, in _scrape
    place = (await self._page.xpath(result_xpath))[i]
IndexError: list index out of range
2021-02-26 17:39:17,047 - WARNING | extractor.py/_scrape/120 | Error occured
Traceback (most recent call last):
  File "extractor.py", line 111, in _scrape
    place = (await self._page.xpath(result_xpath))[i]
IndexError: list index out of range
2021-02-26 17:39:17,052 - WARNING | extractor.py/_scrape/120 | Error occured
Traceback (most recent call last):
  File "extractor.py", line 111, in _scrape
    place = (await self._page.xpath(result_xpath))[i]
IndexError: list index out of range
2021-02-26 17:39:17,056 - WARNING | extractor.py/_scrape/120 | Error occured
Traceback (most recent call last):
  File "extractor.py", line 111, in _scrape
    place = (await self._page.xpath(result_xpath))[i]
IndexError: list index out of range
2021-02-26 17:39:17,062 - WARNING | extractor.py/_scrape/120 | Error occured
Traceback (most recent call last):
  File "extractor.py", line 111, in _scrape
    place = (await self._page.xpath(result_xpath))[i]
IndexError: list index out of range
2021-02-26 17:39:17,067 - WARNING | extractor.py/_scrape/120 | Error occured
Traceback (most recent call last):
  File "extractor.py", line 111, in _scrape
    place = (await self._page.xpath(result_xpath))[i]
IndexError: list index out of range
2021-02-26 17:39:49,279 - WARNING | webdriver.py/_do_retry/67 | Cannot locate xpath retry #1
2021-02-26 17:39:51,929 - ERROR | webdriver.py/_do_retry/70 | Exception found when retrying
Traceback (most recent call last):
  File "..\webdriver.py", line 65, in _do_retry
    await self._page.waitForXPath(xpath, {'visible': True})
  File "C:\Users\khova\AppData\Local\Programs\Python\Python38-32\lib\site-packages\pyppeteer\frame_manager.py", line 855, in __await__
    raise result
pyppeteer.errors.TimeoutError: Waiting for XPath "//*[@class="section-hero-header-title-title GLOBAL__gm2-headline-5"]" failed: timeout 30000ms exceeds.

During handling of the above exception, another exception occurred:

Traceback (most recent call last):
  File "..\webdriver.py", line 63, in _do_retry
    await operation()
  File "C:\Users\khova\AppData\Local\Programs\Python\Python38-32\lib\site-packages\pyppeteer\element_handle.py", line 177, in click
    await self._scrollIntoViewIfNeeded()
  File "C:\Users\khova\AppData\Local\Programs\Python\Python38-32\lib\site-packages\pyppeteer\element_handle.py", line 99, in _scrollIntoViewIfNeeded
    raise ElementHandleError(error)
pyppeteer.errors.ElementHandleError: Node is detached from document
2021-02-26 17:39:52,369 - WARNING | extractor.py/_scrape/120 | Error occured
Traceback (most recent call last):
  File "extractor.py", line 117, in _scrape
    back = (await self._page.xpath(back_xpath))[0]
IndexError: list index out of range
2021-02-26 17:39:52,382 - WARNING | extractor.py/_scrape/120 | Error occured
Traceback (most recent call last):
  File "extractor.py", line 111, in _scrape
    place = (await self._page.xpath(result_xpath))[i]
IndexError: list index out of range
2021-02-26 17:39:56,928 - WARNING | extractor.py/_scrape/120 | Error occured
Traceback (most recent call last):
  File "extractor.py", line 111, in _scrape
    place = (await self._page.xpath(result_xpath))[i]
IndexError: list index out of range
2021-02-26 17:39:56,987 - WARNING | extractor.py/_scrape/120 | Error occured
Traceback (most recent call last):
  File "extractor.py", line 111, in _scrape
    place = (await self._page.xpath(result_xpath))[i]
IndexError: list index out of range
2021-02-26 17:39:57,051 - WARNING | extractor.py/_scrape/120 | Error occured
Traceback (most recent call last):
  File "extractor.py", line 111, in _scrape
    place = (await self._page.xpath(result_xpath))[i]
IndexError: list index out of range
